Traceback (most recent call last):
  File "/home/user/.pyenv/versions/3.10.4/lib/python3.10/runpy.py", line 196, in _run_module_as_main
    return _run_code(code, main_globals, None,
  File "/home/user/.pyenv/versions/3.10.4/lib/python3.10/runpy.py", line 86, in _run_code
    exec(code, run_globals)
  File "/home/user/.pyenv/versions/3.10.4/lib/python3.10/http/server.py", line 1290, in <module>
    test(
  File "/home/user/.pyenv/versions/3.10.4/lib/python3.10/http/server.py", line 1241, in test
    with ServerClass(addr, HandlerClass) as httpd:
  File "/home/user/.pyenv/versions/3.10.4/lib/python3.10/socketserver.py", line 452, in __init__
    self.server_bind()
  File "/home/user/.pyenv/versions/3.10.4/lib/python3.10/http/server.py", line 1284, in server_bind
    return super().server_bind()
  File "/home/user/.pyenv/versions/3.10.4/lib/python3.10/http/server.py", line 136, in server_bind
    socketserver.TCPServer.server_bind(self)
  File "/home/user/.pyenv/versions/3.10.4/lib/python3.10/socketserver.py", line 466, in server_bind
    self.socket.bind(self.server_address)
OSError: [Errno 98] Address already in use
